Workbook

Sheet Boxplots

Sheet ANOVA
A1: Gas-phase sewer concrete | B1: Tin1 ~ H2S + RH + T
B2: Factors | C2: Df | D2: Sum of Sq | E2: RSS | F2: AIC | G2: F value | H2: Pr(>F) | I2: Significance
B3: H2S | C3: 1 | D3: 195.52 | E3: 810.87 | F3: 104.91 | G3: 8.2612 | H3: 0.007969 | I3: **
B4: RH | C4: 1 | D4: 758.02 | E4: 1373.37 | F4: 120.72 | G4: 32.0282 | H4: 5.954e-06 | I4: ***
B5: T | C5: 1 | D5: 1000.08 | E5: 1615.43 | F5: 125.58 | G5: 42.2558 | H5: 6.857e-07 | I5: ***
A6: Partially-submerged concrete sewer | B6: Tin1 ~ H2S + RH + T
B7: H2S | C7: 1 | D7: 1 332.48 | E7: 1223.14 | F7: 117.24 | G7: 9.7058 | H7: 0.004439 | I7: **
B8: RH | C8: 1 | D8: 1 3.68 | E8: 894.33 | F8: 107.85 | G8: 0.1073 | H8: 0.745884
B9: T | C9: 1 | D9: 1 302.44 | E9: 1193.1 | F9: 116.49 | G9: 8.8289 | H9: 0.006309 | I9: **
B10: Tin1 ~ H2S + T
B11: H2S | C11: 1 | D11: 1 332.48 | E11: 1226.81 | F11: 115.33 | G11: 10.0377 | H11: 0.003789 | I11: **
B12: T | C12: 1 | D12: 1 302.44 | E12: 1196.77 | F12: 114.59 | G12: 9.1308 | H12: 0.005447 | I12: **
A14: Significance codes based on the Pr value: | B14: 0-0.001: ***, | C14: 0.001-0.01: **, 0.01-0.05: *, 0.05-0.1: ., 0.1-1: NA

Sheet Tree model

Sheet Data
A1: Location | B1: RH | C1: T | D1: H2S | E1: Tin1 | G1: Location | H1: RH | I1: T | J1: H2S | K1: Tin1
A2: gas | B2: 90 | C2: 17 | D2: 0 | G2: Sewage | H2: 90 | I2: 17 | J2: 0
A3: gas | B3: 90 | C3: 25 | D3: 0 | G3: Sewage | H3: 90 | I3: 25 | J3: 0
A4: gas | B4: 90 | C4: 30 | D4: 0 | G4: Sewage | H4: 90 | I4: 30 | J4: 0
A5: gas | B5: 90 | C5: 17 | D5: 5 | E5: 44.076115 | G5: Sewage | H5: 90 | I5: 17 | J5: 5 | K5: 35.665817
A6: gas | B6: 90 | C6: 25 | D6: 5 | E6: 27.553988 | G6: Sewage | H6: 90 | I6: 25 | J6: 5 | K6: 37.582783
A7: gas | B7: 90 | C7: 30 | D7: 5 | E7: 39.102058 | G7: Sewage | H7: 90 | I7: 30 | J7: 5 | K7: 18.422485
A8: gas | B8: 90 | C8: 17 | D8: 10 | E8: 38.907942 | G8: Sewage | H8: 90 | I8: 17 | J8: 10 | K8: 17.406388
A9: gas | B9: 90 | C9: 25 | D9: 10 | E9: 36.733599 | G9: Sewage | H9: 90 | I9: 25 | J9: 10 | K9: 17.861876
A10: gas | B10: 90 | C10: 30 | D10: 10 | E10: 17.570717 | G10: Sewage | H10: 90 | I10: 30 | J10: 10 | K10: 14.598798
A11: gas | B11: 90 | C11: 17 | D11: 15 | E11: 28.948759 | G11: Sewage | H11: 90 | I11: 17 | J11: 15 | K11: 26.354533
A12: gas | B12: 90 | C12: 25 | D12: 15 | E12: 26.468056 | G12: Sewage | H12: 90 | I12: 25 | J12: 15 | K12: 19.829194
A13: gas | B13: 90 | C13: 30 | D13: 15 | E13: 20.623108 | G13: Sewage | H13: 90 | I13: 30 | J13: 15 | K13: 13.896693
A14: gas | B14: 90 | C14: 17 | D14: 25 | E14: 29.583761 | G14: Sewage | H14: 90 | I14: 17 | J14: 25 | K14: 21.648386
A15: gas | B15: 90 | C15: 25 | D15: 25 | E15: 20.494604 | G15: Sewage | H15: 90 | I15: 25 | J15: 25 | K15: 13.906291
A16: gas | B16: 90 | C16: 30 | D16: 25 | E16: 22.149808 | G16: Sewage | H16: 90 | I16: 30 | J16: 25 | K16: 13.921716
... A19: gas | B19: 90 | C19: 30 | D19: 50 | E19: 15.440642 | G19: Sewage | H19: 90 | I19: 30 | J19: 50 | K19: 13.333333
A20: gas | B20: 100 | C20: 17 | D20: 0 | G20: Sewage | H20: 100 | I20: 17 | J20: 0
A21: gas | B21: 100 | C21: 25 | D21: 0 | G21: Sewage | H21: 100 | I21: 25 | J21: 0
A22: gas | B22: 100 | C22: 30 | D22: 0 | G22: Sewage | H22: 100 | I22: 30 | J22: 0
A23: gas | B23: 100 | C23: 17 | D23: 5 | E23: 29.863114 | G23: Sewage | H23: 100 | I23: 17 | J23: 5 | K23: 27.702759
A24: gas | B24: 100 | C24: 25 | D24: 5 | E24: 21.767544 | G24: Sewage | H24: 100 | I24: 25 | J24: 5 | K24: 19.216374
A25: gas | B25: 100 | C25: 30 | D25: 5 | E25: 11.000833 | G25: Sewage | H25: 100 | I25: 30 | J25: 5 | K25: 15.969622
A26: gas | B26: 100 | C26: 17 | D26: 10 | E26: 24.906971 | G26: Sewage | H26: 100 | I26: 17 | J26: 10 | K26: 25.884911
A27: gas | B27: 100 | C27: 25 | D27: 10 | E27: 18.953398 | G27: Sewage | H27: 100 | I27: 25 | J27: 10 | K27: 34.574668
A28: gas | B28: 100 | C28: 30 | D28: 10 | E28: 9.6519282 | G28: Sewage | H28: 100 | I28: 30 | J28: 10 | K28: 25.4577
A29: gas | B29: 100 | C29: 17 | D29: 15 | E29: 25.012558 | G29: Sewage | H29: 100 | I29: 17 | J29: 15 | K29: 16.063875
A30: gas | B30: 100 | C30: 25 | D30: 15 | E30: 19.551927 | G30: Sewage | H30: 100 | I30: 25 | J30: 15 | K30: 17.296118
A31: gas | B31: 100 | C31: 30 | D31: 15 | E31: 8.6406433 | G31: Sewage | H31: 100 | I31: 30 | J31: 15 | K31: 11.084721
A32: gas | B32: 100 | C32: 17 | D32: 25 | E32: 24.533665 | G32: Sewage | H32: 100 | I32: 17 | J32: 25 | K32: 25.485997
A33: gas | B33: 100 | C33: 25 | D33: 25 | E33: 15.949187 | G33: Sewage | H33: 100 | I33: 25 | J33: 25 | K33: 16.716251
A34: gas | B34: 100 | C34: 30 | D34: 25 | E34: 8.1174104 | G34: Sewage | H34: 100 | I34: 30 | J34: 25 | K34: 12.819964
... A37: gas | B37: 100 | C37: 30 | D37: 50 | E37: 7.6481026 | G37: Sewage | H37: 100 | I37: 30 | J37: 50 | K37: 10.210425

Sheet Tindata
A1: Location | B1: RelHum | C1: Temp | D1: H2S | E1: Tin | F1: Tin-MR predicts
A2: 0 | B2: 90 | C2: 17 | D2: 5 | E2: 44.076115 | F2: ='Multi-Reg'!$B$3+'Multi-Reg'!$B$4*Tindata!A2+'Multi-Reg'!$B$5*Tindata!D2+'Multi-Reg'!$B$6*Tindata!B2+'Multi-Reg'!$B$7*Tindata!C2 -> 32.78937
A3: 0 | B3: 90 | C3: 25 | D3: 5 | E3: 27.553988 | F3: ='Multi-Reg'!$B$3+'Multi-Reg'!$B$4*Tindata!A3+'Multi-Reg'!$B$5*Tindata!D3+'Multi-Reg'!$B$6*Tindata!B3+'Multi-Reg'!$B$7*Tindata!C3 -> 26.10673
A4: 0 | B4: 90 | C4: 30 | D4: 5 | E4: 39.102058 | F4: ='Multi-Reg'!$B$3+'Multi-Reg'!$B$4*Tindata!A4+'Multi-Reg'!$B$5*Tindata!D4+'Multi-Reg'!$B$6*Tindata!B4+'Multi-Reg'!$B$7*Tindata!C4 -> 21.93008
A5: 0 | B5: 90 | C5: 17 | D5: 10 | E5: 38.907942 | F5: ='Multi-Reg'!$B$3+'Multi-Reg'!$B$4*Tindata!A5+'Multi-Reg'!$B$5*Tindata!D5+'Multi-Reg'!$B$6*Tindata!B5+'Multi-Reg'!$B$7*Tindata!C5 -> 31.86827
A6: 0 | B6: 90 | C6: 25 | D6: 10 | E6: 36.733599 | F6: ='Multi-Reg'!$B$3+'Multi-Reg'!$B$4*Tindata!A6+'Multi-Reg'!$B$5*Tindata!D6+'Multi-Reg'!$B$6*Tindata!B6+'Multi-Reg'!$B$7*Tindata!C6 -> 25.18563
A7: 0 | B7: 90 | C7: 30 | D7: 10 | E7: 17.570717 | F7: ='Multi-Reg'!$B$3+'Multi-Reg'!$B$4*Tindata!A7+'Multi-Reg'!$B$5*Tindata!D7+'Multi-Reg'!$B$6*Tindata!B7+'Multi-Reg'!$B$7*Tindata!C7 -> 21.00898
A8: 0 | B8: 90 | C8: 17 | D8: 15 | E8: 28.948759 | F8: ='Multi-Reg'!$B$3+'Multi-Reg'!$B$4*Tindata!A8+'Multi-Reg'!$B$5*Tindata!D8+'Multi-Reg'!$B$6*Tindata!B8+'Multi-Reg'!$B$7*Tindata!C8 -> 30.94717
A9: 0 | B9: 90 | C9: 25 | D9: 15 | E9: 26.468056 | F9: ='Multi-Reg'!$B$3+'Multi-Reg'!$B$4*Tindata!A9+'Multi-Reg'!$B$5*Tindata!D9+'Multi-Reg'!$B$6*Tindata!B9+'Multi-Reg'!$B$7*Tindata!C9 -> 24.26453
A10: 0 | B10: 90 | C10: 30 | D10: 15 | E10: 20.623108 | F10: ='Multi-Reg'!$B$3+'Multi-Reg'!$B$4*Tindata!A10+'Multi-Reg'!$B$5*Tindata!D10+'Multi-Reg'!$B$6*Tindata!B10+'Multi-Reg'!$B$7*Tindata!C10 -> 20.08788
A11: 0 | B11: 90 | C11: 17 | D11: 25 | E11: 29.583761 | F11: ='Multi-Reg'!$B$3+'Multi-Reg'!$B$4*Tindata!A11+'Multi-Reg'!$B$5*Tindata!D11+'Multi-Reg'!$B$6*Tindata!B11+'Multi-Reg'!$B$7*Tindata!C11 -> 29.10497
A12: 0 | B12: 90 | C12: 25 | D12: 25 | E12: 20.494604 | F12: ='Multi-Reg'!$B$3+'Multi-Reg'!$B$4*Tindata!A12+'Multi-Reg'!$B$5*Tindata!D12+'Multi-Reg'!$B$6*Tindata!B12+'Multi-Reg'!$B$7*Tindata!C12 -> 22.42233
A13: 0 | B13: 90 | C13: 30 | D13: 25 | E13: 22.149808 | F13: ='Multi-Reg'!$B$3+'Multi-Reg'!$B$4*Tindata!A13+'Multi-Reg'!$B$5*Tindata!D13+'Multi-Reg'!$B$6*Tindata!B13+'Multi-Reg'!$B$7*Tindata!C13 -> 18.24568
... A23: 0 | B23: 100 | C23: 17 | D23: 15 | E23: 25.012558 | F23: ='Multi-Reg'!$B$3+'Multi-Reg'!$B$4*Tindata!A23+'Multi-Reg'!$B$5*Tindata!D23+'Multi-Reg'!$B$6*Tindata!B23+'Multi-Reg'!$B$7*Tindata!C23 -> 25.56647
A24: 0 | B24: 100 | C24: 25 | D24: 15 | E24: 19.551927 | F24: ='Multi-Reg'!$B$3+'Multi-Reg'!$B$4*Tindata!A24+'Multi-Reg'!$B$5*Tindata!D24+'Multi-Reg'!$B$6*Tindata!B24+'Multi-Reg'!$B$7*Tindata!C24 -> 18.88383 | L24: r= | M24: =SQRT(0.5442) -> 0.73769913
A25: 0 | B25: 100 | C25: 30 | D25: 15 | E25: 8.6406433 | F25: ='Multi-Reg'!$B$3+'Multi-Reg'!$B$4*Tindata!A25+'Multi-Reg'!$B$5*Tindata!D25+'Multi-Reg'!$B$6*Tindata!B25+'Multi-Reg'!$B$7*Tindata!C25 -> 14.70718
A26: 0 | B26: 100 | C26: 17 | D26: 25 | E26: 24.533665 | F26: ='Multi-Reg'!$B$3+'Multi-Reg'!$B$4*Tindata!A26+'Multi-Reg'!$B$5*Tindata!D26+'Multi-Reg'!$B$6*Tindata!B26+'Multi-Reg'!$B$7*Tindata!C26 -> 23.72427
A27: 0 | B27: 100 | C27: 25 | D27: 25 | E27: 15.949187 | F27: ='Multi-Reg'!$B$3+'Multi-Reg'!$B$4*Tindata!A27+'Multi-Reg'!$B$5*Tindata!D27+'Multi-Reg'!$B$6*Tindata!B27+'Multi-Reg'!$B$7*Tindata!C27 -> 17.04163
A28: 0 | B28: 100 | C28: 30 | D28: 25 | E28: 8.1174104 | F28: ='Multi-Reg'!$B$3+'Multi-Reg'!$B$4*Tindata!A28+'Multi-Reg'!$B$5*Tindata!D28+'Multi-Reg'!$B$6*Tindata!B28+'Multi-Reg'!$B$7*Tindata!C28 -> 12.86498
A29: 0 | B29: 100 | C29: 17 | D29: 50 | E29: 25.956495 | F29: ='Multi-Reg'!$B$3+'Multi-Reg'!$B$4*Tindata!A29+'Multi-Reg'!$B$5*Tindata!D29+'Multi-Reg'!$B$6*Tindata!B29+'Multi-Reg'!$B$7*Tindata!C29 -> 19.11877
A30: 0 | B30: 100 | C30: 25 | D30: 50 | E30: 17.789829 | F30: ='Multi-Reg'!$B$3+'Multi-Reg'!$B$4*Tindata!A30+'Multi-Reg'!$B$5*Tindata!D30+'Multi-Reg'!$B$6*Tindata!B30+'Multi-Reg'!$B$7*Tindata!C30 -> 12.43613
A31: 0 | B31: 100 | C31: 30 | D31: 50 | E31: 7.6481026 | F31: ='Multi-Reg'!$B$3+'Multi-Reg'!$B$4*Tindata!A31+'Multi-Reg'!$B$5*Tindata!D31+'Multi-Reg'!$B$6*Tindata!B31+'Multi-Reg'!$B$7*Tindata!C31 -> 8.25948
A32: 1 | B32: 90 | C32: 17 | D32: 5 | E32: 35.665817 | F32: ='Multi-Reg'!$B$3+'Multi-Reg'!$B$4*Tindata!A32+'Multi-Reg'!$B$5*Tindata!D32+'Multi-Reg'!$B$6*Tindata!B32+'Multi-Reg'!$B$7*Tindata!C32 -> 34.47211
A33: 1 | B33: 90 | C33: 25 | D33: 5 | E33: 37.582783 | F33: ='Multi-Reg'!$B$3+'Multi-Reg'!$B$4*Tindata!A33+'Multi-Reg'!$B$5*Tindata!D33+'Multi-Reg'!$B$6*Tindata!B33+'Multi-Reg'!$B$7*Tindata!C33 -> 27.78947
A34: 1 | B34: 90 | C34: 30 | D34: 5 | E34: 18.422485 | F34: ='Multi-Reg'!$B$3+'Multi-Reg'!$B$4*Tindata!A34+'Multi-Reg'!$B$5*Tindata!D34+'Multi-Reg'!$B$6*Tindata!B34+'Multi-Reg'!$B$7*Tindata!C34 -> 23.61282
A35: 1 | B35: 90 | C35: 17 | D35: 10 | E35: 17.406388 | F35: ='Multi-Reg'!$B$3+'Multi-Reg'!$B$4*Tindata!A35+'Multi-Reg'!$B$5*Tindata!D35+'Multi-Reg'!$B$6*Tindata!B35+'Multi-Reg'!$B$7*Tindata!C35 -> 33.55101
A36: 1 | B36: 90 | C36: 25 | D36: 10 | E36: 17.861876 | F36: ='Multi-Reg'!$B$3+'Multi-Reg'!$B$4*Tindata!A36+'Multi-Reg'!$B$5*Tindata!D36+'Multi-Reg'!$B$6*Tindata!B36+'Multi-Reg'!$B$7*Tindata!C36 -> 26.86837
... A61: 1 | B61: 100 | C61: 30 | D61: 50 | E61: 10.210425 | F61: ='Multi-Reg'!$B$3+'Multi-Reg'!$B$4*Tindata!A61+'Multi-Reg'!$B$5*Tindata!D61+'Multi-Reg'!$B$6*Tindata!B61+'Multi-Reg'!$B$7*Tindata!C61 -> 9.94222

Sheet Sheet1
A1: 44.033875 | B1: 44.076115
A2: 36.016399 | B2: 27.553988
A3: 31.79627 | B3: 39.102058
A4: 36.071793 | B4: 38.907942
A5: 29.615572 | B5: 36.733599
A6: 26.411353 | B6: 17.570717
A7: 29.234038 | B7: 28.948759
A8: 24.809313 | B8: 26.468056
A9: 22.527166 | B9: 20.623108
A10: 29.43217 | B10: 29.583761
A11: 18.261396 | B11: 20.494604
A12: 18.027675 | B12: 22.149808
... A30: -2.6296971 | B30: 7.6481026

Sheet Field data validation
A1: Location | B1: RelHum | C1: Temp | D1: H2S | E1: Tin | F1: MR | I1: Site | J1: tin | K1: ANN-GPC | L1: ANN-PSC | M1: MR-GPC | N1: MR-PSC
A2: 1 | B2: 100 | C2: 20.33 | D2: 6.67 | E2: 23.122686 | F2: =96.34+1.68*A2-0.18*D2-0.54*B2-0.84*C2 -> 25.7422 | I2: Perth MS | J2: 9 | K2: 12.438126 | L2: 11.373368 | M2: 25.7422 | N2: 22.3822
A3: -1 | B3: 100 | C3: 20.33 | D3: 6.67 | E3: 19.42379 | F3: =96.34+1.68*A3-0.18*D3-0.54*B3-0.84*C3 -> 22.3822 | I3: Perth Bibra | J3: 15 | K3: 11.628357 | L3: 11.641386 | M3: 27.2686 | N3: 23.9086
A4: 1 | B4: 100 | C4: 19.61 | D4: 1.55 | E4: 24.388462 | F4: =96.34+1.68*A4-0.18*D4-0.54*B4-0.84*C4 -> 27.2686 | I4: Melb. WTS | J4: 16 | K4: 23.122686 | L4: 19.42379 | M4: 4.2748 | N4: 0.9148
A5: -1 | B5: 100 | C5: 19.61 | D5: 1.55 | E5: 20.769117 | F5: =96.34+1.68*A5-0.18*D5-0.54*B5-0.84*C5 -> 23.9086 | I5: Melb. SETS | J5: 24 | K5: 24.388462 | L5: 20.769117 | M5: -72.0044 | N5: -75.3644
A6: 1 | B6: 100 | C6: 26.83 | D6: 95.6 | E6: 12.438126 | F6: =96.34+1.68*A6-0.18*D6-0.54*B6-0.84*C6 -> 4.2748
A7: -1 | B7: 100 | C7: 26.83 | D7: 95.6 | E7: 11.373368 | F7: =96.34+1.68*A7-0.18*D7-0.54*B7-0.84*C7 -> 0.9148
A8: 1 | B8: 89.3 | C8: 27.96 | D8: 546.2 | E8: 11.628357 | F8: =96.34+1.68*A8-0.18*D8-0.54*B8-0.84*C8 -> -72.0044
A9: -1 | B9: 89.3 | C9: 27.96 | D9: 546.2 | E9: 11.641386 | F9: =96.34+1.68*A9-0.18*D9-0.54*B9-0.84*C9 -> -75.3644

Sheet Multi-Reg
A1: Coefficients:
B2: Estimate | C2: Std. Error | D2: t value | E2: Pr(>|t|)
A3: (Intercept) | B3: 96.33738 | C3: 15.03248 | D3: 6.409 | E3: 3.49e-08 | F3: ***
A4: Location | B4: 1.68274 | C4: 0.76729 | D4: 2.193 | E4: 0.032548 | F4: *
A5: H2S | B5: -0.18422 | C5: 0.04814 | D5: -3.827 | E5: 0.000334 | F5: ***
A6: RH | B6: -0.53807 | C6: 0.15346 | D6: -3.506 | E6: 0.000913 | F6: ***
A7: T | B7: -0.83533 | C7: 0.14331 | D7: -5.829 | E7: 3.04e-07 | F7: ***
A8: ---
A9: Signif. codes: 0 ‘***’ 0.001 ‘**’ 0.01 ‘*’ 0.05 ‘.’ 0.1 ‘ ’ 1
A11: Residual standard error: 5.943 on 55 degrees of freedom
A12: (12 observations deleted due to missingness)
A13: Multiple R-squared: 0.5444, Adjusted R-squared: 0.5113
A14: F-statistic: 16.43 on 4 and 55 DF, p-value: 6.52e-09

Sheet ANN sensitivity
A1: Location | B1: H2S | C1: RH | D1: T | E1: ti | O1: Location | P1: H2S | Q1: RH | R1: T | S1: ti | U1: Location | V1: H2S | W1: RH | X1: T | Y1: ti
A2: 1 | B2: 0 | C2: 100 | D2: 25 | E2: 28.691488 | O2: 1 | P2: 25 | Q2: 100 | R2: 0 | S2: 28.582939 | U2: 1 | V2: 25 | W2: 90 | X2: 25 | Y2: 27.432008
A3: 1 | B3: 1 | C3: 100 | D3: 25 | E3: 28.684235 | O3: 1 | P3: 25 | Q3: 100 | R3: 1 | S3: 28.558639 | U3: 1 | V3: 25 | W3: 90.5 | X3: 25 | Y3: 27.362491
A4: 1 | B4: 2 | C4: 100 | D4: 25 | E4: 28.672166 | O4: 1 | P4: 25 | Q4: 100 | R4: 2 | S4: 28.531149 | U4: 1 | V4: 25 | W4: 91 | X4: 25 | Y4: 27.289677
A5: 1 | B5: 3 | C5: 100 | D5: 25 | E5: 28.656404 | O5: 1 | P5: 25 | Q5: 100 | R5: 3 | S5: 28.500062 | U5: 1 | V5: 25 | W5: 91.5 | X5: 25 | Y5: 27.213447
A6: 1 | B6: 4 | C6: 100 | D6: 25 | E6: 28.637154 | O6: 1 | P6: 25 | Q6: 100 | R6: 4 | S6: 28.464923 | U6: 1 | V6: 25 | W6: 92 | X6: 25 | Y6: 27.133677
A7: 1 | B7: 5 | C7: 100 | D7: 25 | E7: 28.61417 | O7: 1 | P7: 25 | Q7: 100 | R7: 5 | S7: 28.425223 | U7: 1 | V7: 25 | W7: 92.5 | X7: 25 | Y7: 27.050245
A8: 1 | B8: 6 | C8: 100 | D8: 25 | E8: 28.586954 | O8: 1 | P8: 25 | Q8: 100 | R8: 6 | S8: 28.380396 | U8: 1 | V8: 25 | W8: 93 | X8: 25 | Y8: 26.963029
A9: 1 | B9: 7 | C9: 100 | D9: 25 | E9: 28.554835 | O9: 1 | P9: 25 | Q9: 100 | R9: 7 | S9: 28.329813 | U9: 1 | V9: 25 | W9: 93.5 | X9: 25 | Y9: 26.871906
A10: 1 | B10: 8 | C10: 100 | D10: 25 | E10: 28.516991 | O10: 1 | P10: 25 | Q10: 100 | R10: 8 | S10: 28.272777 | U10: 1 | V10: 25 | W10: 94 | X10: 25 | Y10: 26.776756
A11: 1 | B11: 9 | C11: 100 | D11: 25 | E11: 28.472452 | O11: 1 | P11: 25 | Q11: 100 | R11: 9 | S11: 28.208516 | U11: 1 | V11: 25 | W11: 94.5 | X11: 25 | Y11: 26.677459
A12: 1 | B12: 10 | C12: 100 | D12: 25 | E12: 28.420084 | O12: 1 | P12: 25 | Q12: 100 | R12: 10 | S12: 28.136183 | U12: 1 | V12: 25 | W12: 95 | X12: 25 | Y12: 26.5739
A13: 1 | B13: 11 | C13: 100 | D13: 25 | E13: 28.358576 | O13: 1 | P13: 25 | Q13: 100 | R13: 11 | S13: 28.054847 | U13: 1 | V13: 25 | W13: 95.5 | X13: 25 | Y13: 26.465966
... A26: 1 | B26: 24 | C26: 100 | D26: 25 | E26: 25.726188 | O26: 1 | P26: 25 | Q26: 100 | R26: 24 | S26: 25.621438 | U26: -1 | V26: 25 | W26: 91.5 | X26: 25 | Y26: 28.601711
A27: 1 | B27: 25 | C27: 100 | D27: 25 | E27: 25.281751 | O27: 1 | P27: 25 | Q27: 100 | R27: 25 | S27: 25.281751 | V27: 25 | W27: 92 | X27: 25 | Y27: 28.592849
A28: 1 | B28: 26 | C28: 100 | D28: 25 | E28: 24.790051 | O28: 1 | P28: 25 | Q28: 100 | R28: 26 | S28: 24.91513 | U28: -1 | V28: 25 | W28: 92.5 | X28: 25 | Y28: 28.583358
A29: 1 | B29: 27 | C29: 100 | D29: 25 | E29: 24.251121 | O29: 1 | P29: 25 | Q29: 100 | R29: 27 | S29: 24.521513 | U29: -1 | V29: 25 | W29: 93 | X29: 25 | Y29: 28.57326
A30: 1 | B30: 28 | C30: 100 | D30: 25 | E30: 23.666444 | O30: 1 | P30: 25 | Q30: 100 | R30: 28 | S30: 24.101292 | U30: -1 | V30: 25 | W30: 93.5 | X30: 25 | Y30: 28.562558
A31: 1 | B31: 29 | C31: 100 | D31: 25 | E31: 23.039141 | O31: 1 | P31: 25 | Q31: 100 | R31: 29 | S31: 23.655364 | U31: -1 | V31: 25 | W31: 94 | X31: 25 | Y31: 28.551237
A32: 1 | B32: 30 | C32: 100 | D32: 25 | E32: 22.374074 | O32: 1 | P32: 25 | Q32: 100 | R32: 30 | S32: 23.185173 | U32: -1 | V32: 25 | W32: 94.5 | X32: 25 | Y32: 28.539276
A33: 1 | B33: 31 | C33: 100 | D33: 25 | E33: 21.677814 | O33: -1 | P33: 25 | Q33: 100 | R33: 0 | S33: 28.747683 | U33: -1 | V33: 25 | W33: 95 | X33: 25 | Y33: 28.526647
A34: 1 | B34: 32 | C34: 100 | D34: 25 | E34: 20.958463 | O34: -1 | P34: 25 | Q34: 100 | R34: 1 | S34: 28.745285 | U34: -1 | V34: 25 | W34: 95.5 | X34: 25 | Y34: 28.513317
A35: 1 | B35: 33 | C35: 100 | D35: 25 | E35: 20.225329 | O35: -1 | P35: 25 | Q35: 100 | R35: 2 | S35: 28.742565 | U35: -1 | V35: 25 | W35: 96 | X35: 25 | Y35: 28.499251
A36: 1 | B36: 34 | C36: 100 | D36: 25 | E36: 19.488467 | O36: -1 | P36: 25 | Q36: 100 | R36: 3 | S36: 28.739479 | U36: -1 | V36: 25 | W36: 96.5 | X36: 25 | Y36: 28.484412
A37: 1 | B37: 35 | C37: 100 | D37: 25 | E37: 18.758134 | O37: -1 | P37: 25 | Q37: 100 | R37: 4 | S37: 28.735979 | U37: -1 | V37: 25 | W37: 97 | X37: 25 | Y37: 28.468759
A38: 1 | B38: 36 | C38: 100 | D38: 25 | E38: 18.044233 | O38: -1 | P38: 25 | Q38: 100 | R38: 5 | S38: 28.732009 | U38: -1 | V38: 25 | W38: 97.5 | X38: 25 | Y38: 28.45225
A39: 1 | B39: 37 | C39: 100 | D39: 25 | E39: 17.355781 | O39: -1 | P39: 25 | Q39: 100 | R39: 6 | S39: 28.727507 | U39: -1 | V39: 25 | W39: 98 | X39: 25 | Y39: 28.434839
... A43: 1 | B43: 41 | C43: 100 | D43: 25 | E43: 14.986032 | O43: -1 | P43: 25 | Q43: 100 | R43: 10 | S43: 28.702603 | U43: -1 | V43: 25 | W43: 100 | X43: 25 | Y43: 28.355208
A44: 1 | B44: 42 | C44: 100 | D44: 25 | E44: 14.507342 | O44: -1 | P44: 25 | Q44: 100 | R44: 11 | S44: 28.694165
A45: 1 | B45: 43 | C45: 100 | D45: 25 | E45: 14.075701 | O45: -1 | P45: 25 | Q45: 100 | R45: 12 | S45: 28.684601
A46: 1 | B46: 44 | C46: 100 | D46: 25 | E46: 13.689663 | O46: -1 | P46: 25 | Q46: 100 | R46: 13 | S46: 28.673761
A47: 1 | B47: 45 | C47: 100 | D47: 25 | E47: 13.34693 | O47: -1 | P47: 25 | Q47: 100 | R47: 14 | S47: 28.661477
A48: 1 | B48: 46 | C48: 100 | D48: 25 | E48: 13.044606 | O48: -1 | P48: 25 | Q48: 100 | R48: 15 | S48: 28.64756
A49: 1 | B49: 47 | C49: 100 | D49: 25 | E49: 12.779427 | O49: -1 | P49: 25 | Q49: 100 | R49: 16 | S49: 28.631795
A50: 1 | B50: 48 | C50: 100 | D50: 25 | E50: 12.547942 | O50: -1 | P50: 25 | Q50: 100 | R50: 17 | S50: 28.613941
A51: 1 | B51: 49 | C51: 100 | D51: 25 | E51: 12.346641 | O51: -1 | P51: 25 | Q51: 100 | R51: 18 | S51: 28.593727
A52: 1 | B52: 50 | C52: 100 | D52: 25 | E52: 12.172034 | O52: -1 | P52: 25 | Q52: 100 | R52: 19 | S52: 28.570848
A53: -1 | B53: 0 | C53: 100 | D53: 25 | E53: 27.788547 | O53: -1 | P53: 25 | Q53: 100 | R53: 20 | S53: 28.54496
A54: -1 | B54: 1 | C54: 100 | D54: 25 | E54: 27.802127 | O54: -1 | P54: 25 | Q54: 100 | R54: 21 | S54: 28.515678
A55: -1 | B55: 2 | C55: 100 | D55: 25 | E55: 27.833426 | O55: -1 | P55: 25 | Q55: 100 | R55: 22 | S55: 28.482572
...

Sheet Sensitivity graph
