Workbook

Sheet Raw原始数据
A1: Location | B1: H2S | C1: RH | D1: T | E1: Y1rate | F1: Y2rate | G1: Y3rate | H1: Ravg | I1: Location | J1: H2S | K1: RH | L1: T | M1: Y1rate | N1: Y2rate | O1: Y3rate | P1: Ravg
A2: GPC | B2: 50 | C2: 100 | D2: 17 | E2: 3.025 | F2: 1.6136685 | G2: 1.3766443 | H2: =AVERAGE(F2:G2) -> 1.4951564 | I2: PSC | J2: 50 | K2: 100 | L2: 17 | M2: 8.5500021 | N2: 5.1725007 | O2: 2.3402584 | P2: =AVERAGE(N2:O2) -> 3.7563796
A3: GPC | B3: 50 | C3: 100 | D3: 25 | E3: 2.4075 | F3: 1.7963303 | G3: 1.4548741 | H3: =AVERAGE(F3:G3) -> 1.6256022 | I3: PSC | J3: 50 | K3: 100 | L3: 25 | M3: 5.66 | N3: 4.2788423 | O3: 3.5613965 | P3: =AVERAGE(N3:O3) -> 3.9201194
A4: GPC | B4: 50 | C4: 100 | D4: 30 | E4: 3.7972514 | F4: 1.3122898 | G4: 1.8084686 | H4: =AVERAGE(F4:G4) -> 1.5603792 | I4: PSC | J4: 50 | K4: 100 | L4: 30 | M4: 3.1485473 | O4: 2.3598616 | P4: =AVERAGE(N4:O4) -> 2.3598616
A5: GPC | B5: 25 | C5: 100 | D5: 17 | E5: 2.557505 | F5: 1.2373406 | G5: 1.9560976 | H5: =AVERAGE(F5:G5) -> 1.5967191 | I5: PSC | J5: 25 | K5: 100 | L5: 17 | M5: 5.9117946 | N5: 2.6876331 | O5: 1.4575047 | P5: =AVERAGE(N5:O5) -> 2.0725689
A6: GPC | B6: 25 | C6: 100 | D6: 25 | E6: 1.913 | F6: 1.0823034 | G6: 2.1527569 | H6: =AVERAGE(F6:G6) -> 1.6175301 | I6: PSC | J6: 25 | K6: 100 | L6: 25 | M6: 5.587 | N6: 2.7945498 | O6: 2.5696043 | P6: =AVERAGE(N6:O6) -> 2.6820771
A7: GPC | B7: 25 | C7: 100 | D7: 30 | E7: 2.2650965 | F7: 1.3801731 | G7: 1.1237624 | H7: =AVERAGE(F7:G7) -> 1.2519677 | I7: PSC | J7: 25 | K7: 100 | L7: 30 | M7: 6.6533827 | N7: 4.4584303 | O7: 1.5604098 | P7: =AVERAGE(N7:O7) -> 3.0094201
A8: GPC | B8: 15 | C8: 100 | D8: 17 | E8: 2.8418604 | F8: 1.2045122 | G8: 0.87850706 | H8: =AVERAGE(F8:G8) -> 1.0415096 | I8: PSC | J8: 15 | K8: 100 | L8: 17 | M8: 6.4 | N8: 2.0329612 | O8: 1.7206671 | P8: =AVERAGE(N8:O8) -> 1.8768141
A9: GPC | B9: 15 | C9: 100 | D9: 25 | E9: 1.488 | F9: 1.4000717 | G9: 1.2598114 | H9: =AVERAGE(F9:G9) -> 1.3299415 | I9: PSC | J9: 15 | K9: 100 | L9: 25 | M9: 3.661 | N9: 2.7982784 | O9: 1.6089231 | P9: =AVERAGE(N9:O9) -> 2.2036008
A10: GPC | B10: 15 | C10: 100 | D10: 30 | E10: 3.6147923 | F10: 1.5649413 | G10: 1.5670604 | H10: =AVERAGE(F10:G10) -> 1.5660008 | I10: PSC | J10: 15 | K10: 100 | L10: 30 | M10: 2.8 | N10: 0.38553095 | O10: 0.68491098 | P10: =AVERAGE(N10:O10) -> 0.53522097
A11: GPC | B11: 10 | C11: 100 | D11: 17 | E11: 3.4362697 | F11: 1.2109139 | G11: 1.5853965 | H11: =AVERAGE(F11:G11) -> 1.3981552 | I11: PSC | J11: 10 | K11: 100 | L11: 17 | M11: 4.6100209 | N11: 1.5639335 | O11: 1.4876627 | P11: =AVERAGE(N11:O11) -> 1.5257981
A12: GPC | B12: 10 | C12: 100 | D12: 25 | E12: 4.62 | F12: 0.37084558 | G12: 1.6707533 | H12: =AVERAGE(F12:G12) -> 1.0207995 | I12: PSC | J12: 10 | K12: 100 | L12: 25 | M12: 3.281 | N12: 1.4389695 | O12: 1.5966733 | P12: =AVERAGE(N12:O12) -> 1.5178214
A13: GPC | B13: 10 | C13: 100 | D13: 30 | E13: 2.9664699 | F13: 1.2364871 | G13: 1.5674871 | H13: =AVERAGE(F13:G13) -> 1.4019871 | I13: PSC | J13: 10 | K13: 100 | L13: 30 | M13: 4.4 | N13: 2.1120524 | O13: 2.3506624 | P13: =AVERAGE(N13:O13) -> 2.2313574
A14: GPC | B14: 5 | C14: 100 | D14: 17 | E14: 3.3394836 | F14: 1.254699 | G14: 1.0321102 | H14: =AVERAGE(F14:G14) -> 1.1434046 | I14: PSC | J14: 5 | K14: 100 | L14: 17 | M14: 2.4218967 | N14: 1.2279337 | O14: 1.2761141 | P14: =AVERAGE(N14:O14) -> 1.2520239
A15: GPC | B15: 5 | C15: 100 | D15: 25 | E15: 4.00689 | F15: 0.95104343 | G15: 0.72920902 | H15: =AVERAGE(F15:G15) -> 0.84012623 | I15: PSC | J15: 5 | K15: 100 | L15: 25 | M15: 2.552 | N15: 1.4657817 | O15: 1.1480169 | P15: =AVERAGE(N15:O15) -> 1.3068993
A16: GPC | B16: 5 | C16: 100 | D16: 30 | E16: 3.3447324 | F16: 0.2468149 | G16: 1.1636824 | H16: =AVERAGE(F16:G16) -> 0.70524863 | I16: PSC | J16: 5 | K16: 100 | L16: 30 | M16: 2.691482 | N16: 2.2571348 | O16: 1.6359431 | P16: =AVERAGE(N16:O16) -> 1.946539
... A37: GPC | B37: 0 | C37: 90 | D37: 30 | E37: 1.574154 | F37: 0.81170395 | G37: 1.3262459 | H37: =AVERAGE(F37:G37) -> 1.0689749 | I37: PSC | J37: 0 | K37: 90 | L37: 30 | M37: 3.6099712 | N37: 2.0128024 | O37: 0.67288 | P37: =AVERAGE(N37:O37) -> 1.3428412
C41: 单独类别 | D41: 一共
C42: 36 | D42: =36*2 -> 72

Sheet CorrRate
A1: Location | B1: H2S | C1: RH | D1: Temperature | E1: CorrRate
A2: 0 | B2: 50 | C2: 100 | D2: 17 | E2: 1.6136685
A3: 0 | B3: 50 | C3: 100 | D3: 25 | E3: 1.7963303
A4: 0 | B4: 50 | C4: 100 | D4: 30 | E4: 1.3122898
A5: 0 | B5: 25 | C5: 100 | D5: 17 | E5: 1.2373406
A6: 0 | B6: 25 | C6: 100 | D6: 25 | E6: 1.0823034
A7: 0 | B7: 25 | C7: 100 | D7: 30 | E7: 1.3801731
A8: 0 | B8: 15 | C8: 100 | D8: 17 | E8: 1.2045122
A9: 0 | B9: 15 | C9: 100 | D9: 25 | E9: 1.4000717
A10: 0 | B10: 15 | C10: 100 | D10: 30 | E10: 1.5649413
A11: 0 | B11: 10 | C11: 100 | D11: 17 | E11: 1.2109139
A12: 0 | B12: 10 | C12: 100 | D12: 25 | E12: 0.37084558
A13: 0 | B13: 10 | C13: 100 | D13: 30 | E13: 1.2364871
... A72: 0 | B72: 0 | C72: 90 | D72: 25 | E72: 0.75523725
A73: 0 | B73: 0 | C73: 90 | D73: 30 | E73: 1.3262459 | F73: 72个气 | G73: 第二年和第三年的速率都放进来了
A74: 1 | B74: 50 | C74: 100 | D74: 17 | E74: 5.1725007
A75: 1 | B75: 50 | C75: 100 | D75: 25 | E75: 4.2788423
A76: 1 | B76: 50 | C76: 100 | D76: 30 | E76: 2.01
A77: 1 | B77: 25 | C77: 100 | D77: 17 | E77: 2.6876331
A78: 1 | B78: 25 | C78: 100 | D78: 25 | E78: 2.7945498
A79: 1 | B79: 25 | C79: 100 | D79: 30 | E79: 4.4584303
A80: 1 | B80: 15 | C80: 100 | D80: 17 | E80: 2.0329612
A81: 1 | B81: 15 | C81: 100 | D81: 25 | E81: 2.7982784
A82: 1 | B82: 15 | C82: 100 | D82: 30 | E82: 0.38553095
A83: 1 | B83: 10 | C83: 100 | D83: 17 | E83: 1.5639335
A84: 1 | B84: 10 | C84: 100 | D84: 25 | E84: 1.4389695
A85: 1 | B85: 10 | C85: 100 | D85: 30 | E85: 2.1120524
... A144: 1 | B144: 0 | C144: 90 | D144: 25 | E144: 0.27644
A145: 1 | B145: 0 | C145: 90 | D145: 30 | E145: 0.67288 | F145: 72个液
B150: 总的 | C150: 单独类别两年 | E150: 单独类别一年
B151: 144 | C151: =B151/2 -> 72 | E151: 36

Sheet CorrRavg
A1: ANC | B1: Location | C1: H2S | D1: RH | E1: Temperature | F1: CorrRate | G1: MR-Predict
A2: 2430 | B2: 1 | C2: 50 | D2: 100 | E2: 17 | F2: 1.4951564 | G2: =MultiReg!$I$19+MultiReg!$I$20*CorrRavg!C2+MultiReg!$I$21*CorrRavg!D2 -> 1.602927
A3: 2430 | B3: 1 | C3: 50 | D3: 100 | E3: 25 | F3: 1.6256022 | G3: =MultiReg!$I$19+MultiReg!$I$20*CorrRavg!C3+MultiReg!$I$21*CorrRavg!D3 -> 1.602927
A4: 2430 | B4: 1 | C4: 50 | D4: 100 | E4: 30 | F4: 1.5603792 | G4: =MultiReg!$I$19+MultiReg!$I$20*CorrRavg!C4+MultiReg!$I$21*CorrRavg!D4 -> 1.602927
A5: 2430 | B5: 1 | C5: 25 | D5: 100 | E5: 17 | F5: 1.5967191 | G5: =MultiReg!$I$19+MultiReg!$I$20*CorrRavg!C5+MultiReg!$I$21*CorrRavg!D5 -> 1.306627
A6: 2430 | B6: 1 | C6: 25 | D6: 100 | E6: 25 | F6: 1.6175301 | G6: =MultiReg!$I$19+MultiReg!$I$20*CorrRavg!C6+MultiReg!$I$21*CorrRavg!D6 -> 1.306627
A7: 2430 | B7: 1 | C7: 25 | D7: 100 | E7: 30 | F7: 1.2519677 | G7: =MultiReg!$I$19+MultiReg!$I$20*CorrRavg!C7+MultiReg!$I$21*CorrRavg!D7 -> 1.306627
A8: 2430 | B8: 1 | C8: 15 | D8: 100 | E8: 17 | F8: 1.0415096 | G8: =MultiReg!$I$19+MultiReg!$I$20*CorrRavg!C8+MultiReg!$I$21*CorrRavg!D8 -> 1.188107
A9: 2430 | B9: 1 | C9: 15 | D9: 100 | E9: 25 | F9: 1.3299415 | G9: =MultiReg!$I$19+MultiReg!$I$20*CorrRavg!C9+MultiReg!$I$21*CorrRavg!D9 -> 1.188107
A10: 2430 | B10: 1 | C10: 15 | D10: 100 | E10: 30 | F10: 1.5660008 | G10: =MultiReg!$I$19+MultiReg!$I$20*CorrRavg!C10+MultiReg!$I$21*CorrRavg!D10 -> 1.188107
A11: 2430 | B11: 1 | C11: 10 | D11: 100 | E11: 17 | F11: 1.3981552 | G11: =MultiReg!$I$19+MultiReg!$I$20*CorrRavg!C11+MultiReg!$I$21*CorrRavg!D11 -> 1.128847
A12: 2430 | B12: 1 | C12: 10 | D12: 100 | E12: 25 | F12: 1.0207995 | G12: =MultiReg!$I$19+MultiReg!$I$20*CorrRavg!C12+MultiReg!$I$21*CorrRavg!D12 -> 1.128847
A13: 2430 | B13: 1 | C13: 10 | D13: 100 | E13: 30 | F13: 1.4019871 | G13: =MultiReg!$I$19+MultiReg!$I$20*CorrRavg!C13+MultiReg!$I$21*CorrRavg!D13 -> 1.128847
... A23: 2430 | B23: 1 | C23: 25 | D23: 90 | E23: 17 | F23: 1.5005227 | G23: =MultiReg!$I$19+MultiReg!$I$20*CorrRavg!C23+MultiReg!$I$21*CorrRavg!D23 -> 1.013297
A24: 2430 | B24: 1 | C24: 25 | D24: 90 | E24: 25 | F24: 0.64470129 | G24: =MultiReg!$I$19+MultiReg!$I$20*CorrRavg!C24+MultiReg!$I$21*CorrRavg!D24 -> 1.013297 | V24: Start pH
A25: 2430 | B25: 1 | C25: 25 | D25: 90 | E25: 30 | F25: 1.4548278 | G25: =MultiReg!$I$19+MultiReg!$I$20*CorrRavg!C25+MultiReg!$I$21*CorrRavg!D25 -> 1.013297 | U25: Fresh: | V25: 10.6 | W25: -> | X25: 1 | Y25: mol-H+/kg
A26: 2430 | B26: 1 | C26: 15 | D26: 90 | E26: 17 | F26: 0.58618824 | G26: =MultiReg!$I$19+MultiReg!$I$20*CorrRavg!C26+MultiReg!$I$21*CorrRavg!D26 -> 0.894777 | U26: Old: | V26: 7.8 | X26: 0.4 | Y26: mol-H+/kg
A27: 2430 | B27: 1 | C27: 15 | D27: 90 | E27: 25 | F27: 0.88366086 | G27: =MultiReg!$I$19+MultiReg!$I$20*CorrRavg!C27+MultiReg!$I$21*CorrRavg!D27 -> 0.894777
A28: 2430 | B28: 1 | C28: 15 | D28: 90 | E28: 30 | F28: 0.87068996 | G28: =MultiReg!$I$19+MultiReg!$I$20*CorrRavg!C28+MultiReg!$I$21*CorrRavg!D28 -> 0.894777
A29: 2430 | B29: 1 | C29: 10 | D29: 90 | E29: 17 | F29: 1.0420788 | G29: =MultiReg!$I$19+MultiReg!$I$20*CorrRavg!C29+MultiReg!$I$21*CorrRavg!D29 -> 0.835517
A30: 2430 | B30: 1 | C30: 10 | D30: 90 | E30: 25 | F30: 0.94439402 | G30: =MultiReg!$I$19+MultiReg!$I$20*CorrRavg!C30+MultiReg!$I$21*CorrRavg!D30 -> 0.835517
A31: 2430 | B31: 1 | C31: 10 | D31: 90 | E31: 30 | F31: 0.97205592 | G31: =MultiReg!$I$19+MultiReg!$I$20*CorrRavg!C31+MultiReg!$I$21*CorrRavg!D31 -> 0.835517
A32: 2430 | B32: 1 | C32: 5 | D32: 90 | E32: 17 | F32: 0.65088823 | G32: =MultiReg!$I$19+MultiReg!$I$20*CorrRavg!C32+MultiReg!$I$21*CorrRavg!D32 -> 0.776257
A33: 2430 | B33: 1 | C33: 5 | D33: 90 | E33: 25 | F33: 0.85667527 | G33: =MultiReg!$I$19+MultiReg!$I$20*CorrRavg!C33+MultiReg!$I$21*CorrRavg!D33 -> 0.776257
A34: 2430 | B34: 1 | C34: 5 | D34: 90 | E34: 30 | F34: 0.46665137 | G34: =MultiReg!$I$19+MultiReg!$I$20*CorrRavg!C34+MultiReg!$I$21*CorrRavg!D34 -> 0.776257
A35: 2430 | B35: 1 | C35: 0 | D35: 90 | E35: 17 | F35: 0.5883577 | G35: =MultiReg!$I$19+MultiReg!$I$20*CorrRavg!C35+MultiReg!$I$21*CorrRavg!D35 -> 0.716997
A36: 2430 | B36: 1 | C36: 0 | D36: 90 | E36: 25 | F36: 0.72152911 | G36: =MultiReg!$I$19+MultiReg!$I$20*CorrRavg!C36+MultiReg!$I$21*CorrRavg!D36 -> 0.716997
A37: 2430 | B37: 1 | C37: 0 | D37: 90 | E37: 30 | F37: 1.0689749 | G37: =MultiReg!$I$19+MultiReg!$I$20*CorrRavg!C37+MultiReg!$I$21*CorrRavg!D37 -> 0.716997
A38: 2430 | B38: -1 | C38: 50 | D38: 100 | E38: 17 | F38: 3.7563796 | G38: =MultiReg!$T$39+MultiReg!$T$40*CorrRavg!C38 -> 3.427418
A39: 2430 | B39: -1 | C39: 50 | D39: 100 | E39: 25 | F39: 3.9201194 | G39: =MultiReg!$T$39+MultiReg!$T$40*CorrRavg!C39 -> 3.427418
A40: 2430 | B40: -1 | C40: 50 | D40: 100 | E40: 30 | F40: 2.3598616 | G40: =MultiReg!$T$39+MultiReg!$T$40*CorrRavg!C40 -> 3.427418
A41: 2430 | B41: -1 | C41: 25 | D41: 100 | E41: 17 | F41: 2.0725689 | G41: =MultiReg!$T$39+MultiReg!$T$40*CorrRavg!C41 -> 2.312093
A42: 2430 | B42: -1 | C42: 25 | D42: 100 | E42: 25 | F42: 2.6820771 | G42: =MultiReg!$T$39+MultiReg!$T$40*CorrRavg!C42 -> 2.312093
A43: 2430 | B43: -1 | C43: 25 | D43: 100 | E43: 30 | F43: 3.0094201 | G43: =MultiReg!$T$39+MultiReg!$T$40*CorrRavg!C43 -> 2.312093
A44: 2430 | B44: -1 | C44: 15 | D44: 100 | E44: 17 | F44: 1.8768141 | G44: =MultiReg!$T$39+MultiReg!$T$40*CorrRavg!C44 -> 1.865963
A45: 2430 | B45: -1 | C45: 15 | D45: 100 | E45: 25 | F45: 2.2036008 | G45: =MultiReg!$T$39+MultiReg!$T$40*CorrRavg!C45 -> 1.865963
A46: 2430 | B46: -1 | C46: 15 | D46: 100 | E46: 30 | F46: 0.53522097 | G46: =MultiReg!$T$39+MultiReg!$T$40*CorrRavg!C46 -> 1.865963
A47: 2430 | B47: -1 | C47: 10 | D47: 100 | E47: 17 | F47: 1.5257981 | G47: =MultiReg!$T$39+MultiReg!$T$40*CorrRavg!C47 -> 1.642898
A48: 2430 | B48: -1 | C48: 10 | D48: 100 | E48: 25 | F48: 1.5178214 | G48: =MultiReg!$T$39+MultiReg!$T$40*CorrRavg!C48 -> 1.642898
A49: 2430 | B49: -1 | C49: 10 | D49: 100 | E49: 30 | F49: 2.2313574 | G49: =MultiReg!$T$39+MultiReg!$T$40*CorrRavg!C49 -> 1.642898
...

Sheet Lab&Field data
A1: Location | B1: H2S | C1: RH | D1: Temperature | E1: CorrRate
A2: 1 | B2: 50 | C2: 100 | D2: 17 | E2: 1.4951564
A3: 1 | B3: 50 | C3: 100 | D3: 25 | E3: 1.6256022
A4: 1 | B4: 50 | C4: 100 | D4: 30 | E4: 1.5603792
A5: 1 | B5: 25 | C5: 100 | D5: 17 | E5: 1.5967191
A6: 1 | B6: 25 | C6: 100 | D6: 25 | E6: 1.6175301
A7: 1 | B7: 25 | C7: 100 | D7: 30 | E7: 1.2519677
A8: 1 | B8: 15 | C8: 100 | D8: 17 | E8: 1.0415096
A9: 1 | B9: 15 | C9: 100 | D9: 25 | E9: 1.3299415
A10: 1 | B10: 15 | C10: 100 | D10: 30 | E10: 1.5660008
A11: 1 | B11: 10 | C11: 100 | D11: 17 | E11: 1.3981552
A12: 1 | B12: 10 | C12: 100 | D12: 25 | E12: 1.0207995
A13: 1 | B13: 10 | C13: 100 | D13: 30 | E13: 1.4019871
... A72: -1 | B72: 0 | C72: 90 | D72: 25 | E72: 0.66332669
A73: -1 | B73: 0 | C73: 90 | D73: 30 | E73: 1.3428412 | F73: 72个实验室
A74: 1 | B74: 1.5 | C74: 100 | D74: 19.7 | E74: 0.85
A75: 1 | B75: 6 | C75: 100 | D75: 20.7 | E75: 6.3
A76: 1 | B76: 125.3 | C76: 96.5 | D76: 25.8 | E76: 10.9
A77: 1 | B77: 422.1 | C77: 90 | D77: 27 | E77: 5.4
A78: 1 | B78: 11.9 | C78: 94 | D78: 17.1 | E78: 3.5
A79: 1 | B79: 12.4 | C79: 86 | D79: 25.8 | E79: 1.1
A80: 1 | B80: 140.3 | C80: 94 | D80: 20.7 | E80: 4.4
A81: 1 | B81: 2.7 | C81: 94 | D81: 21.6 | E81: 0.6
A82: 1 | B82: 2.2 | C82: 94 | D82: 21.3 | E82: 0.7 | F82: 9个野外实验

Sheet SP1B data

Sheet ANN performance
A1: Site | B1: H2S | C1: RH | D1: Temperature | E1: Cr Fresh | F1: Cr Precorroded | G1: ANN-GPC | H1: ANN-PSC | I1: MR-GPC | J1: MR-PSC | K1: R-ave | L1: R-LpF
A2: Melbourne SETS | B2: 1.5 | C2: 100 | D2: 19.7 | E2: 0.6 | F2: 1.1 | G2: 0.73127485 | H2: 0.80493661 | I2: =1.03-0.45*1+0.0282*B2 -> 0.6223 | J2: =1.03-0.45*(-1)+0.0282*B2 -> 1.5223 | K2: =AVERAGE(E2:F2) -> 0.85 | L2: 1.266534
A3: Melbourne WTS | B3: 6 | C3: 100 | D3: 20.7 | E3: 6.1 | F3: 6.5 | G3: 0.87527724 | H3: 1.1781788 | I3: =1.03-0.45*1+0.0282*B3 -> 0.7492 | J3: =1.03-0.45*(-1)+0.0282*B3 -> 1.6492 | K3: =AVERAGE(E3:F3) -> 6.3 | L3: 1.2612849
A4: Perth MS | B4: 125.3 | C4: 96.5 | D4: 25.8 | E4: 11.6 | F4: 10.2 | G4: 3.4009539 | H4: 3.4566517 | I4: =1.03-0.45*1+0.0282*B4 -> 4.11346 | J4: =1.03-0.45*(-1)+0.0282*B4 -> 5.01346 | K4: =AVERAGE(E4:F4) -> 10.9 | L4: 8.0270485
A5: Perth Bibra Lake | B5: 422.1 | C5: 90 | D5: 27 | E5: 5.3 | F5: 5.5 | G5: 3.4567331 | H5: 3.4567343 | I5: =1.03-0.45*1+0.0282*B5 -> 12.48322 | J5: =1.03-0.45*(-1)+0.0282*B5 -> 13.38322 | K5: =AVERAGE(E5:F5) -> 5.4 | L5: 4.4421966
A6: Morton | B6: 11.9 | C6: 94 | D6: 17.1 | G6: 1.1700032 | H6: 1.8827919 | I6: =1.03-0.45*1+0.0282*B6 -> 0.91558 | J6: =1.03-0.45*(-1)+0.0282*B6 -> 1.81558 | K6: 3.5 | L6: 1.2888972
A7: P&J (Perth) | B7: 12.4 | C7: 86 | D7: 25.8 | G7: 1.0196958 | H7: 1.7373899 | I7: =1.03-0.45*1+0.0282*B7 -> 0.92968 | J7: =1.03-0.45*(-1)+0.0282*B7 -> 1.82968 | K7: 1.1 | L7: 1.1851276
A8: P&J (Melbourne) | B8: 140.3 | C8: 94 | D8: 20.7 | G8: 3.436846 | H8: 3.4567326 | I8: =1.03-0.45*1+0.0282*B8 -> 4.53646 | J8: =1.03-0.45*(-1)+0.0282*B8 -> 5.43646 | K8: 4.4 | L8: 6.0140159
A9: Sydney A | B9: 2.7 | C9: 94 | D9: 21.6 | F9: 0.6 | G9: 0.82572505 | H9: 0.9420334 | I9: =1.03-0.45*1+0.0282*B9 -> 0.65614 | J9: =1.03-0.45*(-1)+0.0282*B9 -> 1.55614 | K9: 0.6 | L9: 1.2318481
A10: Sydney B | B10: 2.2 | C10: 94 | D10: 21.3 | F10: 0.7 | G10: 0.80243201 | H10: 0.84063497 | I10: =1.03-0.45*1+0.0282*B10 -> 0.64204 | J10: =1.03-0.45*(-1)+0.0282*B10 -> 1.54204 | K10: 0.7 | L10: 1.2341295
A29: Reasons for the discrepency:
A30: 1. Different conditions in the lab from the field?
A31: 2. Fluctuation of the conditions in the field, cant use average value for the prediction. Some correction factors need to be used along with AVG values.
A32: 3. Other unidentified factors.
A33: 4. Reliability of field environmental data
M42: 1.266534 | N42: 1.2612849 | O42: 8.0270485 | P42: 4.4421966 | Q42: 1.2888972 | R42: 1.1851276 | S42: 6.0140159 | T42: 1.2318481 | U42: 1.2341295

Sheet MultiReg
A1: Coefficients:
B2: Estimate | C2: Std. Error | D2: t value | E2: Pr(>|t|) | H2: Estimate | I2: Std. Error | J2: t value | K2: Pr(>|t|) | O2: Estimate | P2: Std. Error | Q2: t value | R2: Pr(>|t|)
A3: (Intercept) | B3: -0.62661 | C3: 1.260699 | D3: -0.497 | E3: 0.621 | G3: (Intercept) | H3: 0.199362 | I3: 0.308652 | J3: 0.646 | K3: 0.521 | N3: (Intercept) | O3: 0.577037 | P3: 0.113787 | Q3: 5.071 | R3: 3.18e-06 | S3: ***
A4: Location | B4: 0.906389 | C4: 0.128634 | D4: 7.046 | E4: 1.25e-09 | F4: *** | G4: Location | H4: 0.906389 | I4: 0.128119 | J4: 7.075 | K4: 1.04e-09 | L4: *** | N4: Location | O4: 0.906389 | P4: 0.128795 | Q4: 7.037 | R4: 1.14e-09 | S4: ***
A5: H2S | B5: 0.028233 | C5: 0.003893 | D5: 7.252 | E5: 5.36e-10 | F5: *** | G5: H2S | H5: 0.028233 | I5: 0.003878 | J5: 7.281 | K5: 4.41e-10 | L5: *** | N5: H2S | O5: 0.028233 | P5: 0.003898 | Q5: 7.243 | R5: 4.82e-10 | S5: ***
A6: RH | B6: 0.008694 | C6: 0.012863 | D6: 0.676 | E6: 0.501 | G6: T | H6: 0.015736 | I6: 0.011964 | J6: 1.315 | K6: 0.193
A7: T | B7: 0.015736 | C7: 0.012013 | D7: 1.31 | E7: 0.195
A8: ---
A9: Signif. codes: 0 ‘***’ 0.001 ‘**’ 0.01 ‘*’ 0.05 ‘.’ 0.1 ‘ ’ 1
A11: Residual standard error: 0.5457 on 67 degrees of freedom
A12: Multiple R-squared: 0.6091, Adjusted R-squared: 0.5858
A13: F-statistic: 26.1 on 4 and 67 DF, p-value: 4.61e-13
A15: GAS
A17: Coefficients: (1 not defined because of singularities) | H17: Coefficients: (1 not defined because of singularities)
B18: Estimate | C18: Std. Error | D18: t value | E18: Pr(>|t|) | I18: Estimate | J18: Std. Error | K18: t value | L18: Pr(>|t|)
A19: (Intercept) | B19: -1.961345 | C19: 0.834272 | D19: -2.351 | E19: 0.02505 | F19: * | H19: (Intercept) | I19: -1.922973 | J19: 0.80021 | K19: -2.403 | L19: 0.02204 | M19: *
A20: H2S | B20: 0.011852 | C20: 0.00258 | D20: 4.594 | E20: 6.43e-05 | F20: *** | H20: H2S | I20: 0.011852 | J20: 0.002542 | K20: 4.663 | L20: 4.97e-05 | M20: ***
A21: RH | B21: 0.029333 | C21: 0.008523 | D21: 3.441 | E21: 0.00163 | F21: ** | H21: RH | I21: 0.029333 | J21: 0.008399 | K21: 3.493 | L21: 0.00138 | M21: **
A22: T | B22: 0.001599 | C22: 0.00796 | D22: 0.201 | E22: 0.84207 | H22: ---
A23: --- | H23: Signif. codes: 0 ‘***’ 0.001 ‘**’ 0.01 ‘*’ 0.05 ‘.’ 0.1 ‘ ’ 1
A24: Signif. codes: 0 ‘***’ 0.001 ‘**’ 0.01 ‘*’ 0.05 ‘.’ 0.1 ‘ ’ 1
A26: Residual standard error: 0.2557 on 32 degrees of freedom | H26: Residual standard error: 0.252 on 33 degrees of freedom
A27: Multiple R-squared: 0.5076, Adjusted R-squared: 0.4615 | H27: Multiple R-squared: 0.507, Adjusted R-squared: 0.4771
A28: F-statistic: 11 on 3 and 32 DF, p-value: 4.033e-05 | H28: F-statistic: 16.97 on 2 and 33 DF, p-value: 8.544e-06
A30: Submerged
A32: Residuals:
B33: Min | C33: 1Q | D33: Median | E33: 3Q | F33: Max | J33: Residuals: | S33: Residuals:
A34: -1.44549 | B34: -0.32406 | C34: 0.03712 | D34: 0.40097 | E34: 1.19507 | K34: Min | L34: 1Q | M34: Median | N34: 3Q | O34: Max | T34: Min | U34: 1Q | V34: Median | W34: 3Q | X34: Max
J35: -1.50521 | K35: -0.27899 | L35: 0.00315 | M35: 0.35975 | N35: 1.25479 | S35: -1.32597 | T35: -0.41677 | U35: -0.01637 | V35: 0.3425 | W35: 1.43403
A36: Coefficients: | B36: (1 | C36: not | D36: defined | E36: because | F36: of | G36: singularities)
B37: Estimate | C37: Std. | D37: Error | E37: t | F37: value | G37: Pr(>|t|) | J37: Coefficients: | S37: Coefficients:
A38: (Intercept) | B38: 1.614514 | C38: 1.948319 | D38: 0.829 | E38: 0.413 | K38: Estimate | L38: Std. | M38: Error | N38: t | O38: value | P38: Pr(>|t|) | T38: Estimate | U38: Std. | V38: Error | W38: t | X38: value | Y38: Pr(>|t|)
A39: H2S | B39: 0.044613 | C39: 0.006025 | D39: 7.405 | E39: 2e-08 | F39: *** | J39: (Intercept) | K39: 0.479792 | L39: 0.464527 | M39: 1.033 | N39: 0.309 | S39: (Intercept) | T39: 1.196768 | U39: 0.146982 | V39: 8.142 | W39: 1.7e-09 | X39: ***
A40: RH | B40: -0.011944 | C40: 0.019905 | D40: -0.6 | E40: 0.553 | J40: H2S | K40: 0.044613 | L40: 0.005966 | M40: 7.478 | N40: 1.35e-08 | O40: *** | S40: H2S | T40: 0.044613 | U40: 0.006107 | V40: 7.305 | W40: 1.84e-08 | X40: ***
A41: T | B41: 0.029874 | C41: 0.018589 | D41: 1.607 | E41: 0.118 | J41: T | K41: 0.029874 | L41: 0.018408 | M41: 1.623 | N41: 0.114 | S41: ---
A42: --- | J42: --- | S42: Signif. codes: 0 ‘***’ 0.001 ‘**’ 0.01 ‘*’ 0.05 ‘.’ 0.1 ‘ ’ 1
A43: Signif. codes: 0 ‘***’ 0.001 ‘**’ 0.01 ‘*’ 0.05 ‘.’ 0.1 ‘ ’ 1 | J43: Signif. codes: 0 ‘***’ 0.001 ‘**’ 0.01 ‘*’ 0.05 ‘.’ 0.1 ‘ ’ 1
S44: Residual | T44: standard | U44: error: | V44: 0.6054 | W44: on | X44: 34 | Y44: degrees | Z44: of | AA44: freedom
A45: Residual | B45: standard | C45: error: | D45: 0.5972 | E45: on | F45: 32 | G45: degrees | H45: of | I45: freedom | J45: Residual | K45: standard | L45: error: | M45: 0.5913 | N45: on | O45: 33 | P45: degrees | Q45: of | R45: freedom | S45: Multiple | T45: R-squared: | U45: 0.6108 | V45: Adjusted | W45: R-squared: | X45: 0.5994
A46: Multiple | B46: R-squared: | C46: 0.6436 | D46: Adjusted | E46: R-squared: | F46: 0.6102 | J46: Multiple | K46: R-squared: | L46: 0.6396 | M46: Adjusted | N46: R-squared: | O46: 0.6177 | S46: F-statistic: | T46: 53.36 | U46: on | V46: 1 | W46: and | X46: 34 | Y46: DF | Z46: p-value: | AA46: 1.844e-08
...

Sheet ANN sensitivity
A1: Location | B1: H2S | C1: RH | D1: T | E1: CorrRate | O1: Location | P1: H2S | Q1: RH | R1: T | S1: CorrRate | U1: Location | V1: H2S | W1: RH | X1: T | Y1: CorrRate
A2: 1 | B2: 0 | C2: 100 | D2: 25 | E2: 0.78533362 | O2: 1 | P2: 25 | Q2: 100 | R2: 0 | S2: 2.4853753 | U2: 1 | V2: 25 | W2: 90 | X2: 25 | Y2: 0.98119048
A3: 1 | B3: 1 | C3: 100 | D3: 25 | E3: 0.81581945 | O3: 1 | P3: 25 | Q3: 100 | R3: 1 | S3: 2.4587589 | U3: 1 | V3: 25 | W3: 90.5 | X3: 25 | Y3: 0.91885763
A4: 1 | B4: 2 | C4: 100 | D4: 25 | E4: 0.84937822 | O4: 1 | P4: 25 | Q4: 100 | R4: 2 | S4: 2.4288894 | U4: 1 | V4: 25 | W4: 91 | X4: 25 | Y4: 0.8928419
A5: 1 | B5: 3 | C5: 100 | D5: 25 | E5: 0.88583012 | O5: 1 | P5: 25 | Q5: 100 | R5: 3 | S5: 2.3955346 | U5: 1 | V5: 25 | W5: 91.5 | X5: 25 | Y5: 0.90008948
A6: 1 | B6: 4 | C6: 100 | D6: 25 | E6: 0.924724 | O6: 1 | P6: 25 | Q6: 100 | R6: 4 | S6: 2.3584962 | U6: 1 | V6: 25 | W6: 92 | X6: 25 | Y6: 0.93060318
A7: 1 | B7: 5 | C7: 100 | D7: 25 | E7: 0.96534662 | O7: 1 | P7: 25 | Q7: 100 | R7: 5 | S7: 2.3176218 | U7: 1 | V7: 25 | W7: 92.5 | X7: 25 | Y7: 0.97068986
A8: 1 | B8: 6 | C8: 100 | D8: 25 | E8: 1.0067744 | O8: 1 | P8: 25 | Q8: 100 | R8: 6 | S8: 2.2728178 | U8: 1 | V8: 25 | W8: 93 | X8: 25 | Y8: 1.0085179
A9: 1 | B9: 7 | C9: 100 | D9: 25 | E9: 1.0479645 | O9: 1 | P9: 25 | Q9: 100 | R9: 7 | S9: 2.224059 | U9: 1 | V9: 25 | W9: 93.5 | X9: 25 | Y9: 1.038289
A10: 1 | B10: 8 | C10: 100 | D10: 25 | E10: 1.0878695 | O10: 1 | P10: 25 | Q10: 100 | R10: 8 | S10: 2.1713918 | U10: 1 | V10: 25 | W10: 94 | X10: 25 | Y10: 1.0607653
A11: 1 | B11: 9 | C11: 100 | D11: 25 | E11: 1.1255535 | O11: 1 | P11: 25 | Q11: 100 | R11: 9 | S11: 2.1149275 | U11: 1 | V11: 25 | W11: 94.5 | X11: 25 | Y11: 1.0811193
A12: 1 | B12: 10 | C12: 100 | D12: 25 | E12: 1.1602846 | O12: 1 | P12: 25 | Q12: 100 | R12: 10 | S12: 2.0548194 | U12: 1 | V12: 25 | W12: 95 | X12: 25 | Y12: 1.1061007
A13: 1 | B13: 11 | C13: 100 | D13: 25 | E13: 1.1915891 | O13: 1 | P13: 25 | Q13: 100 | R13: 11 | S13: 1.9912192 | U13: 1 | V13: 25 | W13: 95.5 | X13: 25 | Y13: 1.1414868
... A43: 1 | B43: 41 | C43: 100 | D43: 25 | E43: 1.5310173 | O43: -1 | P43: 25 | Q43: 100 | R43: 10 | S43: 1.5378038 | U43: -1 | V43: 25 | W43: 100 | X43: 25 | Y43: 2.6971822
A44: 1 | B44: 42 | C44: 100 | D44: 25 | E44: 1.5420819 | O44: -1 | P44: 25 | Q44: 100 | R44: 11 | S44: 1.6031779
A45: 1 | B45: 43 | C45: 100 | D45: 25 | E45: 1.5532637 | O45: -1 | P45: 25 | Q45: 100 | R45: 12 | S45: 1.6768863
A46: 1 | B46: 44 | C46: 100 | D46: 25 | E46: 1.564553 | O46: -1 | P46: 25 | Q46: 100 | R46: 13 | S46: 1.7611612
A47: 1 | B47: 45 | C47: 100 | D47: 25 | E47: 1.5759409 | O47: -1 | P47: 25 | Q47: 100 | R47: 14 | S47: 1.8586929
A48: 1 | B48: 46 | C48: 100 | D48: 25 | E48: 1.587419 | O48: -1 | P48: 25 | Q48: 100 | R48: 15 | S48: 1.9715517
A49: 1 | B49: 47 | C49: 100 | D49: 25 | E49: 1.5989798 | O49: -1 | P49: 25 | Q49: 100 | R49: 16 | S49: 2.0989186
A50: 1 | B50: 48 | C50: 100 | D50: 25 | E50: 1.6106161 | O50: -1 | P50: 25 | Q50: 100 | R50: 17 | S50: 2.2345711
A51: 1 | B51: 49 | C51: 100 | D51: 25 | E51: 1.6223212 | O51: -1 | P51: 25 | Q51: 100 | R51: 18 | S51: 2.3668834
A52: 1 | B52: 50 | C52: 100 | D52: 25 | E52: 1.6340889 | O52: -1 | P52: 25 | Q52: 100 | R52: 19 | S52: 2.4830653
A53: -1 | B53: 0 | C53: 100 | D53: 25 | E53: 0.93597489 | O53: -1 | P53: 25 | Q53: 100 | R53: 20 | S53: 2.5746616
A54: -1 | B54: 1 | C54: 100 | D54: 25 | E54: 1.0118931 | O54: -1 | P54: 25 | Q54: 100 | R54: 21 | S54: 2.6396245
A55: -1 | B55: 2 | C55: 100 | D55: 25 | E55: 1.0853731 | O55: -1 | P55: 25 | Q55: 100 | R55: 22 | S55: 2.6804713
... A63: -1 | B63: 10 | C63: 100 | D63: 25 | E63: 1.5796101 | O63: -1 | P63: 25 | Q63: 100 | R63: 30 | S63: 2.4869086
A64: -1 | B64: 11 | C64: 100 | D64: 25 | E64: 1.636387
A65: -1 | B65: 12 | C65: 100 | D65: 25 | E65: 1.6941749
A66: -1 | B66: 13 | C66: 100 | D66: 25 | E66: 1.7535831
A67: -1 | B67: 14 | C67: 100 | D67: 25 | E67: 1.8151663
A68: -1 | B68: 15 | C68: 100 | D68: 25 | E68: 1.8794111
A69: -1 | B69: 16 | C69: 100 | D69: 25 | E69: 1.9467222
A70: -1 | B70: 17 | C70: 100 | D70: 25 | E70: 2.0174068
A71: -1 | B71: 18 | C71: 100 | D71: 25 | E71: 2.0916582
A72: -1 | B72: 19 | C72: 100 | D72: 25 | E72: 2.1695385
A73: -1 | B73: 20 | C73: 100 | D73: 25 | E73: 2.250963
A74: -1 | B74: 21 | C74: 100 | D74: 25 | E74: 2.3356892
A75: -1 | B75: 22 | C75: 100 | D75: 25 | E75: 2.4233108
... A103: -1 | B103: 50 | C103: 100 | D103: 25 | E103: 3.6824856
...

Sheet Sheet1
A1: Location | B1: H2S | C1: RH | D1: Temperature | E1: CorrRate
A2: GP | B2: 50 | C2: 100 | D2: 17 | E2: 1.4951564
A3: GP | B3: 50 | C3: 100 | D3: 25 | E3: 1.6256022
A4: GP | B4: 50 | C4: 100 | D4: 30 | E4: 1.5603792
A5: GP | B5: 25 | C5: 100 | D5: 17 | E5: 1.5967191
A6: GP | B6: 25 | C6: 100 | D6: 25 | E6: 1.6175301
A7: GP | B7: 25 | C7: 100 | D7: 30 | E7: 1.2519677
A8: GP | B8: 15 | C8: 100 | D8: 17 | E8: 1.0415096
A9: GP | B9: 15 | C9: 100 | D9: 25 | E9: 1.3299415
A10: GP | B10: 15 | C10: 100 | D10: 30 | E10: 1.5660008
A11: GP | B11: 10 | C11: 100 | D11: 17 | E11: 1.3981552
A12: GP | B12: 10 | C12: 100 | D12: 25 | E12: 1.0207995
A13: GP | B13: 10 | C13: 100 | D13: 30 | E13: 1.4019871
... A73: PS | B73: 0 | C73: 90 | D73: 30 | E73: 1.3428412
B74: 总72数据
